Workbook

Sheet Mapping
A1: Control | B1: Theme | C1: Control name | D1: Applicable | E1: Status | F1: NIST CSF 2.0 function | G1: NIST CSF 2.0 category | H1: DORA article(s) | I1: DORA area | J1: DORA fit | K1: Note
A2: 5.1 | B2: Organizational | C2: Policies for information security | D2: Yes | E2: Partially implemented | F2: Govern | G2: GV.PO Policy | H2: Art. 6 | I2: ICT risk management (Chapter II) | J2: Direct
A3: 5.2 | B3: Organizational | C3: Information security roles and responsibilities | D3: Yes | E3: Partially implemented | F3: Govern | G3: GV.RR Roles, Responsibilities and Authorities | H3: Art. 5 | I3: ICT risk management (Chapter II) | J3: Direct | K3: Management body carries the responsibility under DORA.
A4: 5.3 | B4: Organizational | C4: Segregation of duties | D4: Yes | E4: Planned | F4: Protect | G4: PR.AA Identity Management, Authentication and Access Control | H4: Art. 9 | I4: ICT risk management (Chapter II) | J4: Partial
A5: 5.4 | B5: Organizational | C5: Management responsibilities | D5: Yes | E5: Partially implemented | F5: Govern | G5: GV.RR Roles, Responsibilities and Authorities | H5: Art. 5 | I5: ICT risk management (Chapter II) | J5: Direct
A6: 5.5 | B6: Organizational | C6: Contact with authorities | D6: Yes | E6: Planned | F6: Respond | G6: RS.CO Incident Response Reporting and Communication | H6: Art. 14, 19 | I6: ICT risk management (Chapter II) | J6: Direct | K6: DORA reporting goes to the competent authority; GDPR to the data protection authority.
A7: 5.6 | B7: Organizational | C7: Contact with special interest groups | D7: Yes | E7: Planned | F7: Identify | G7: ID.RA Risk Assessment | H7: Art. 45 | I7: Information sharing (Chapter VI) | J7: Direct | K7: Information sharing under DORA is voluntary.
A8: 5.7 | B8: Organizational | C8: Threat intelligence | D8: Yes | E8: Planned | F8: Identify | G8: ID.RA Risk Assessment | H8: Art. 13 | I8: ICT risk management (Chapter II) | J8: Partial
A9: 5.8 | B9: Organizational | C9: Information security in project management | D9: Yes | E9: Planned | F9: Govern | G9: GV.RM Risk Management Strategy | H9: Art. 9 | I9: ICT risk management (Chapter II) | J9: Partial
A10: 5.9 | B10: Organizational | C10: Inventory of information and other associated assets | D10: Yes | E10: Partially implemented | F10: Identify | G10: ID.AM Asset Management | H10: Art. 8 | I10: ICT risk management (Chapter II) | J10: Direct | K10: DORA expects a full ICT asset identification and classification.
A11: 5.10 | B11: Organizational | C11: Acceptable use of information and other associated assets | D11: Yes | E11: Planned | F11: Govern | G11: GV.PO Policy | H11: Art. 9 | I11: ICT risk management (Chapter II) | J11: Partial
A12: 5.11 | B12: Organizational | C12: Return of assets | D12: Yes | E12: Planned | F12: Identify | G12: ID.AM Asset Management | H12: Art. 8 | I12: ICT risk management (Chapter II) | J12: Partial
A13: 5.12 | B13: Organizational | C13: Classification of information | D13: Yes | E13: Planned | F13: Identify | G13: ID.AM Asset Management | H13: Art. 8 | I13: ICT risk management (Chapter II) | J13: Direct
A14: 5.13 | B14: Organizational | C14: Labelling of information | D14: Yes | E14: Planned | F14: Protect | G14: PR.DS Data Security | H14: Art. 9 | I14: ICT risk management (Chapter II) | J14: Partial
A15: 5.14 | B15: Organizational | C15: Information transfer | D15: Yes | E15: Planned | F15: Protect | G15: PR.DS Data Security | H15: Art. 9 | I15: ICT risk management (Chapter II) | J15: Direct | K15: Secure data transfer.
A16: 5.15 | B16: Organizational | C16: Access control | D16: Yes | E16: Partially implemented | F16: Protect | G16: PR.AA Identity Management, Authentication and Access Control | H16: Art. 9 | I16: ICT risk management (Chapter II) | J16: Direct
A17: 5.16 | B17: Organizational | C17: Identity management | D17: Yes | E17: Partially implemented | F17: Protect | G17: PR.AA Identity Management, Authentication and Access Control | H17: Art. 9 | I17: ICT risk management (Chapter II) | J17: Direct
A18: 5.17 | B18: Organizational | C18: Authentication information | D18: Yes | E18: Partially implemented | F18: Protect | G18: PR.AA Identity Management, Authentication and Access Control | H18: Art. 9 | I18: ICT risk management (Chapter II) | J18: Direct
A19: 5.18 | B19: Organizational | C19: Access rights | D19: Yes | E19: Partially implemented | F19: Protect | G19: PR.AA Identity Management, Authentication and Access Control | H19: Art. 9 | I19: ICT risk management (Chapter II) | J19: Direct
A20: 5.19 | B20: Organizational | C20: Information security in supplier relationships | D20: Yes | E20: Planned | F20: Govern | G20: GV.SC Cybersecurity Supply Chain Risk Management | H20: Art. 28 | I20: ICT third-party risk (Chapter V) | J20: Direct
A21: 5.20 | B21: Organizational | C21: Addressing information security within supplier agreements | D21: Yes | E21: Partially implemented | F21: Govern | G21: GV.SC Cybersecurity Supply Chain Risk Management | H21: Art. 30 | I21: ICT third-party risk (Chapter V) | J21: Direct | K21: DORA lists key contract terms: audit rights, exit, subcontracting, incident support.
A22: 5.21 | B22: Organizational | C22: Managing information security in the ICT supply chain | D22: Yes | E22: Planned | F22: Govern | G22: GV.SC Cybersecurity Supply Chain Risk Management | H22: Art. 28, 29 | I22: ICT third-party risk (Chapter V) | J22: Direct | K22: Concentration risk (Art. 29) is not part of ISO 27001.
A23: 5.22 | B23: Organizational | C23: Monitoring, review and change management of supplier services | D23: Yes | E23: Planned | F23: Govern | G23: GV.SC Cybersecurity Supply Chain Risk Management | H23: Art. 28 | I23: ICT third-party risk (Chapter V) | J23: Direct
A24: 5.23 | B24: Organizational | C24: Information security for use of cloud services | D24: Yes | E24: Partially implemented | F24: Govern | G24: GV.SC Cybersecurity Supply Chain Risk Management | H24: Art. 28, 30 | I24: ICT third-party risk (Chapter V) | J24: Direct | K24: Cloud providers are ICT third-party providers under DORA.
A25: 5.24 | B25: Organizational | C25: Information security incident management planning and preparation | D25: Yes | E25: Planned | F25: Respond | G25: RS.MA Incident Management | H25: Art. 17 | I25: Incident management and reporting (Chapter III) | J25: Direct
A26: 5.25 | B26: Organizational | C26: Assessment and decision on information security events | D26: Yes | E26: Planned | F26: Detect | G26: DE.AE Adverse Event Analysis | H26: Art. 17, 18 | I26: Incident management and reporting (Chapter III) | J26: Direct | K26: Art. 18 classifies incidents against set criteria.
A27: 5.26 | B27: Organizational | C27: Response to information security incidents | D27: Yes | E27: Planned | F27: Respond | G27: RS.MA Incident Management | H27: Art. 11, 17 | I27: ICT risk management (Chapter II) | J27: Direct
A28: 5.27 | B28: Organizational | C28: Learning from information security incidents | D28: Yes | E28: Planned | F28: Identify | G28: ID.IM Improvement | H28: Art. 13 | I28: ICT risk management (Chapter II) | J28: Direct
A29: 5.28 | B29: Organizational | C29: Collection of evidence | D29: Yes | E29: Planned | F29: Respond | G29: RS.AN Incident Analysis | H29: Art. 17 | I29: Incident management and reporting (Chapter III) | J29: Partial
A30: 5.29 | B30: Organizational | C30: Information security during disruption | D30: Yes | E30: Planned | F30: Recover | G30: RC.RP Incident Recovery Plan Execution | H30: Art. 11 | I30: ICT risk management (Chapter II) | J30: Direct
A31: 5.30 | B31: Organizational | C31: ICT readiness for business continuity | D31: Yes | E31: Planned | F31: Recover | G31: RC.RP Incident Recovery Plan Execution | H31: Art. 11, 12 | I31: ICT risk management (Chapter II) | J31: Direct | K31: DORA expects tested continuity and recovery plans.
A32: 5.31 | B32: Organizational | C32: Legal, statutory, regulatory and contractual requirements | D32: Yes | E32: Partially implemented | F32: Govern | G32: GV.OC Organizational Context | H32: Art. 6 | I32: ICT risk management (Chapter II) | J32: Partial | K32: Regulatory requirements feed the ICT risk framework.
A33: 5.32 | B33: Organizational | C33: Intellectual property rights | D33: Yes | E33: Planned | F33: Govern | G33: GV.OC Organizational Context | H33: - | I33: Not covered by DORA | J33: None | K33: Outside DORA.
A34: 5.33 | B34: Organizational | C34: Protection of records | D34: Yes | E34: Planned | F34: Protect | G34: PR.DS Data Security | H34: Art. 9 | I34: ICT risk management (Chapter II) | J34: Partial
A35: 5.34 | B35: Organizational | C35: Privacy and protection of PII | D35: Yes | E35: Partially implemented | F35: Govern | G35: GV.OC Organizational Context | H35: - | I35: Not covered by DORA | J35: None | K35: Privacy is covered by GDPR, not DORA.
A36: 5.35 | B36: Organizational | C36: Independent review of information security | D36: Yes | E36: Planned | F36: Govern | G36: GV.OV Oversight | H36: Art. 6 | I36: ICT risk management (Chapter II) | J36: Direct | K36: DORA requires internal audit of the ICT risk framework.
A37: 5.36 | B37: Organizational | C37: Compliance with policies, rules and standards for information security | D37: Yes | E37: Planned | F37: Govern | G37: GV.OV Oversight | H37: Art. 6 | I37: ICT risk management (Chapter II) | J37: Direct
A38: 5.37 | B38: Organizational | C38: Documented operating procedures | D38: Yes | E38: Planned | F38: Govern | G38: GV.PO Policy | H38: Art. 9 | I38: ICT risk management (Chapter II) | J38: Partial
A39: 6.1 | B39: People | C39: Screening | D39: Yes | E39: Planned | F39: Govern | G39: GV.RR Roles, Responsibilities and Authorities | H39: - | I39: Not covered by DORA | J39: None
A40: 6.2 | B40: People | C40: Terms and conditions of employment | D40: Yes | E40: Partially implemented | F40: Govern | G40: GV.RR Roles, Responsibilities and Authorities | H40: - | I40: Not covered by DORA | J40: None
...

Sheet DORA gaps
A1: DORA topic | B1: Article(s) | C1: What DORA expects | D1: Starter kit coverage | E1: Related Annex A controls | F1: Linked risks | G1: Next step
A2: Register of information on ICT third-party arrangements | B2: Art. 28 | C2: A maintained register of all contracts with ICT third-party providers, including which services support critical functions. | D2: Not covered | E2: 5.19, 5.22 | F2: R09 | G2: Create a supplier register using the template from the vendor risk project.
A3: Exit strategies and termination of ICT third-party services | B3: Art. 28 | C3: Documented exit plans and tested alternatives for services that support critical functions. | D3: Not covered | E3: 5.22, 5.30 | F3: R09, R16 | G3: Add an exit plan section for the three key suppliers.
A4: ICT concentration risk | B4: Art. 29 | C4: Assess dependence on a single provider or on providers that are closely connected. | D4: Not covered | E4: 5.21 | F4: R09 | G4: Note in the vendor risk assessment that Azure carries most of StoreSight.
A5: Key contractual provisions | B5: Art. 30 | C5: Contracts must cover service levels, audit and access rights, incident support, sub-outsourcing and exit. | D5: Partly covered | E5: 5.20 | F5: R09 | G5: Compare the three key contracts against an Art. 30 checklist.
A6: Major incident classification and regulatory reporting | B6: Art. 17, 18, 19 | C6: Classify incidents against set criteria and report major ones to the authority in short staged deadlines (initial, intermediate, final). Check the current technical standards for exact times. | D6: Partly covered | E6: 5.24, 5.25, 5.26 | F6: R23, R24 | G6: Add DORA classification criteria and staged timelines next to the NIS2 and GDPR lines in the incident policy.
A7: Digital operational resilience testing programme | B7: Art. 24, 25, 26 | C7: A yearly risk-based testing programme (vulnerability scans, scenario tests); advanced threat-led testing for significant entities. | D7: Partly covered | E7: 8.8, 8.29 | F7: R14, R23 | G7: Write a one-page annual testing plan covering scans, restore test and the tabletop exercise.
A8: ICT business continuity, response and recovery plans | B8: Art. 11, 12 | C8: Tested continuity and recovery plans with recovery time and recovery point targets, and backup restoration tests. | D8: Partly covered | E8: 5.29, 5.30, 8.13, 8.14 | F8: R08, R16 | G8: Set recovery targets for StoreSight and record the first restore test.
A9: Management body accountability and training | B9: Art. 5, 13 | C9: Management approves and oversees the ICT risk framework and keeps its own training current. | D9: Partly covered | E9: 5.2, 5.4, 6.3 | F9: R21 | G9: Add a yearly management review and management training line to the ISMS.
A10: Information-sharing arrangements | B10: Art. 45 | C10: Voluntary exchange of cyber threat information with trusted communities. | D10: Partly covered | E10: 5.6, 5.7 | F10: R14 | G10: Join BSI and vendor advisory feeds (already planned under 5.6).

Sheet Summary
A1: Framework mapping
A2: Havelmetrics GmbH. Personal project on a fictional company.
A3: ISO/IEC 27001:2022 Annex A mapped to NIST CSF 2.0 and DORA
A4: Version 1.0 draft. Indicative mapping, see the How to read sheet.
A6: NIST CSF 2.0 function | B6: Controls | C6: Of which applicable
A7: Govern | B7: =COUNTIF(Mapping!F2:F94,A7) | C7: =COUNTIFS(Mapping!F2:F94,A7,Mapping!D2:D94,"Yes")
A8: Identify | B8: =COUNTIF(Mapping!F2:F94,A8) | C8: =COUNTIFS(Mapping!F2:F94,A8,Mapping!D2:D94,"Yes")
A9: Protect | B9: =COUNTIF(Mapping!F2:F94,A9) | C9: =COUNTIFS(Mapping!F2:F94,A9,Mapping!D2:D94,"Yes")
A10: Detect | B10: =COUNTIF(Mapping!F2:F94,A10) | C10: =COUNTIFS(Mapping!F2:F94,A10,Mapping!D2:D94,"Yes")
A11: Respond | B11: =COUNTIF(Mapping!F2:F94,A11) | C11: =COUNTIFS(Mapping!F2:F94,A11,Mapping!D2:D94,"Yes")
A12: Recover | B12: =COUNTIF(Mapping!F2:F94,A12) | C12: =COUNTIFS(Mapping!F2:F94,A12,Mapping!D2:D94,"Yes")
A13: Total | B13: =SUM(B7:B12) | C13: =SUM(C7:C12)
A15: DORA fit | B15: Controls | C15: Of which applicable
A16: Direct | B16: =COUNTIF(Mapping!J2:J94,A16) | C16: =COUNTIFS(Mapping!J2:J94,A16,Mapping!D2:D94,"Yes")
A17: Partial | B17: =COUNTIF(Mapping!J2:J94,A17) | C17: =COUNTIFS(Mapping!J2:J94,A17,Mapping!D2:D94,"Yes")
A18: None | B18: =COUNTIF(Mapping!J2:J94,A18) | C18: =COUNTIFS(Mapping!J2:J94,A18,Mapping!D2:D94,"Yes")
A19: Total | B19: =SUM(B16:B18) | C19: =SUM(C16:C18)
A21: DORA topics with gaps | B21: Topics
A22: Not covered by the starter kit | B22: =COUNTIF('DORA gaps'!D2:D10,"Not covered")
A23: Partly covered | B23: =COUNTIF('DORA gaps'!D2:D10,"Partly covered")

Sheet How to read
A1: How to read this mapping
A3: Purpose: show that the ISO 27001 ISMS in this repository can be read in the language of two other frameworks that fintech employers use: NIST Cybersecurity Framework 2.0 and the EU Digital Operational Resilience Act (DORA, Regulation (EU) 2022/2554).
A5: Mapping sheet: each of the 93 Annex A controls has one main NIST CSF 2.0 category and the DORA article(s) it supports. Applicability and status come from the Statement of Applicability.
A6: DORA fit: Direct = the topic is named in the article. Partial = covered indirectly by a general requirement to protect or run ICT systems. None = outside DORA (for example privacy, which GDPR covers).
A7: DORA gaps sheet: topics where DORA asks for more than ISO 27001 controls give. These are next steps, not finished work.
A9: Important limits:
A10: 1. DORA applies to financial entities and, through contracts, to their ICT providers. Havelmetrics sells to retail chains, so DORA would not apply directly. The mapping shows readiness for a bank or fintech customer.
A11: 2. This is my own indicative mapping, built from the standards' structure. It is not an official crosswalk and has not been reviewed by a regulator or auditor. Check article details and the technical standards (for example on incident reporting) against the legal text before relying on them.
A12: 3. DORA articles are cited at article level only, not paragraph level.
A13: 4. NIST CSF 2.0 categories are the six functions Govern, Identify, Protect, Detect, Respond and Recover with their categories (GV, ID, PR, DE, RS, RC).
